Code From: `django/core/handers/exception.py` 
Repo Link - https://github.com/django/django


## Code Snippet:

```
def get_exception_response(request, resolver, status_code, exception):
    try:
        callback = resolver.resolve_error_handler(status_code)
        response = callback(request, exception=exception)
    except Exception:
        signals.got_request_exception.send(sender=None, request=request)
        response = handle_uncaught_exception(request, resolver, sys.exc_info())

    return response
```

## Coding Assistant Command: 

`Generate Unit Tests`

## Response:

```
import pytest

from django.core.handlers.exception import get_exception_response


class TestGetExceptionResponse:
    @pytest.fixture
    def resolver(self):
        return Mock()

    @pytest.fixture
    def request(self):
        return Mock()

    @pytest.fixture
    def exception(self):
        return Mock()

    def test_get_exception_response_with_callback(self, resolver, request, exception):
        # Arrange
        callback = Mock(return_value="Response")
        resolver.resolve_error_handler.return_value = callback
        status_code = 404

        # Act
        response = get_exception_response(request, resolver, status_code, exception)

        # Assert
        callback.assert_called_once_with(request, exception=exception)
        assert response == "Response"

    def test_get_exception_response_without_callback(self, resolver, request, exception):
        # Arrange
        resolver.resolve_error_handler.return_value = None
        status_code = 404

        # Act
        response = get_exception_response(request, resolver, status_code, exception)

        # Assert
        resolver.resolve_error_handler.assert_called_once_with(status_code)
        signals.got_request_exception.send.assert_called_once_with(sender=None, request=request)
        handle_uncaught_exception.assert_called_once_with(request, resolver, sys.exc_info())
        assert response == handle_uncaught_exception.return_value
```
